Workbook

Sheet Gas Log
A1: Timestamp | B1: City | C1: State | D1: Brand | E1: Price/Gallon | F1: Odometer | G1: Gallons | H1: Price | I1: Miles | J1: Miles/Gallon | K1: Total Fuel Cost | L1: Total Gallons | M1: MPG | N1: $/mile | O1: Notes | P1: MPG last 5
A2: 40382 | B2: San Diego | C2: California | D2: Dealer | E2: 0 | F2: 4 | G2: 8.7 | H2: 0 | I2: =F2 -> 4 | K2: 0 | L2: =G2 -> 8.7 | Q2: Total Miles | R2: =max(F2:F357) -> 71181
A3: 40385 | B3: San Marcos | C3: California | D3: Shell | E3: 3.319 | F3: 266.7 | G3: 7.137 | H3: 23.69 | I3: =if(G3>0,F3-F2," ") -> 262.7 | J3: =if(G3>0,I3/G3," ") -> 36.808183 | K3: =if(H3>0,K2+H3," ") -> 23.69 | L3: =G3+L2 -> 15.837 | M3: =F3/(L3-8.7) -> 37.368642 | N3: =K3/F3 -> 0.088826397 | Q3: Average Fill (gallons) | R3: =average(G2:G357) -> 6.1806886
A4: 40440 | B4: Campo | C4: California | D4: Golden Acorn | E4: 3.399 | F4: 513 | G4: 6.043 | H4: 20.54 | I4: =if(G4>0,F4-F3," ") -> 246.3 | J4: =if(G4>0,I4/G4," ") -> 40.757902 | K4: =if(H4>0,K3+H4," ") -> 44.23 | L4: =G4+L3 -> 21.88 | M4: =F4/(L4-8.7) -> 38.92261 | N4: =K4/F4 -> 0.086218324 | Q4: Number of Fill-ups | R4: =count(G2:G357) -> 293
A5: 40440 | B5: Eloy | C5: Arizona | D5: Flying J | E5: 2.859 | F5: 819 | G5: 8.304 | H5: 23.74 | I5: =if(G5>0,F5-F4," ") -> 306 | J5: =if(G5>0,I5/G5," ") -> 36.849711 | K5: =if(H5>0,K4+H5," ") -> 67.97 | L5: =G5+L4 -> 30.184 | M5: =F5/(L5-8.7) -> 38.121393 | N5: =K5/F5 -> 0.082991453 | Q5: Average Miles to Fill | R5: =average(I3:I357) -> 243.75685
A6: 40441 | B6: Deming | C6: Arizona | D6: Fina | E6: 2.929 | F6: 1109 | G6: 7.119 | H6: 20.05 | I6: =if(G6>0,F6-F5," ") -> 290 | J6: =if(G6>0,I6/G6," ") -> 40.736058 | K6: =if(H6>0,K5+H6," ") -> 88.02 | L6: =G6+L5 -> 37.303 | M6: =F6/(L6-8.7) -> 38.772157 | N6: =K6/F6 -> 0.079368801 | Q6: Total Fuel Cost | R6: =max(K2:K357) -> 6532.5664
A7: 40441 | B7: Pecos | C7: Texas | D7: Fina | E7: 2.959 | F7: 1413 | G7: 8.476 | H7: 25.08 | I7: =if(G7>0,F7-F6," ") -> 304 | J7: =if(G7>0,I7/G7," ") -> 35.865975 | K7: =if(H7>0,K6+H7," ") -> 113.1 | L7: =G7+L6 -> 45.779 | M7: =F7/(L7-8.7) -> 38.107824 | N7: =K7/F7 -> 0.080042463 | P7: =(sum(I2:I7)/sum(G2:G7)) -> 30.865681 | Q7: Total Fuel (gallons) | R7: =max(L2:L357) -> 1772.9338
A8: 40442 | B8: Abilene | C8: Texas | D8: Fina | E8: 2.739 | F8: 1655 | G8: 5.624 | H8: 15.4 | I8: =if(G8>0,F8-F7," ") -> 242 | J8: =if(G8>0,I8/G8," ") -> 43.029872 | K8: =if(H8>0,K7+H8," ") -> 128.5 | L8: =G8+L7 -> 51.403 | M8: =F8/(L8-8.7) -> 38.756059 | N8: =K8/F8 -> 0.077643505 | P8: =(sum(I3:I8)/sum(G3:G8)) -> 38.662389 | Q8: Overall MPG | R8: =R2/R7 -> 40.148708 | S8: (adjust with new data)
A9: 40444 | B9: Flower Mound | C9: Texas | D9: RaceTrac | E9: 2.769 | F9: 1939 | G9: 7.715 | H9: 21.36 | I9: =if(G9>0,F9-F8," ") -> 284 | J9: =if(G9>0,I9/G9," ") -> 36.811406 | K9: =if(H9>0,K8+H9," ") -> 149.86 | L9: =G9+L8 -> 59.118 | M9: =F9/(L9-8.7) -> 38.458487 | N9: =K9/F9 -> 0.077287261 | P9: =(sum(I4:I9)/sum(G4:G9)) -> 38.638202 | Q9: Best MPG (last 5) | R9: =max(P7:P281) -> 47.103267
A10: 40445 | B10: Blackwell | C10: Oklahoma | D10: Shell | E10: 2.999 | F10: 2205 | G10: 6.165 | H10: 18.49 | I10: =if(G10>0,F10-F9," ") -> 266 | J10: =if(G10>0,I10/G10," ") -> 43.146796 | K10: =if(H10>0,K9+H10," ") -> 168.35 | L10: =G10+L9 -> 65.283 | M10: =F10/(L10-8.7) -> 38.969302 | N10: =K10/F10 -> 0.076349206 | P10: =(sum(I5:I10)/sum(G5:G10)) -> 38.98348 | Q10: Most expensive fuel | R10: =max(E3:E357) -> 5.6731221
A11: 40445 | B11: Matfield Green | C11: Kansas | D11: Shell | E11: 2.959 | F11: 2438 | G11: 7.295 | H11: 21.59 | I11: =if(G11>0,F11-F10," ") -> 233 | J11: =if(G11>0,I11/G11," ") -> 31.939685 | K11: =if(H11>0,K10+H11," ") -> 189.94 | L11: =G11+L10 -> 72.578 | M11: =F11/(L11-8.7) -> 38.166505 | N11: =K11/F11 -> 0.077908121 | P11: =(sum(I6:I11)/sum(G6:G11)) -> 38.189366 | Q11: Least expensive fuel | R11: =min(E3:E357) -> 2.349 | S11: =R10/R11 -> 2.4151222 | T11: Most vs Least
A12: 40450 | B12: St. Louis | C12: Missouri | D12: Conoco | E12: 2.689 | F12: 2744 | G12: 7.851 | H12: 21.11 | I12: =if(G12>0,F12-F11," ") -> 306 | J12: =if(G12>0,I12/G12," ") -> 38.975927 | K12: =if(H12>0,K11+H12," ") -> 211.05 | L12: =G12+L11 -> 80.429 | M12: =F12/(L12-8.7) -> 38.255099 | N12: =K12/F12 -> 0.076913265 | P12: =(sum(I7:I12)/sum(G7:G12)) -> 37.912164
A13: 40451 | B13: Dale | C13: Indiana | D13: Shell | E13: 2.899 | F13: 3035 | G13: 7.002 | H13: 20.3 | I13: =if(G13>0,F13-F12," ") -> 291 | J13: =if(G13>0,I13/G12," ") -> 37.065342 | K13: =if(H13>0,K12+H13," ") -> 231.35 | L13: =G13+L12 -> 87.431 | M13: =F13/(L13-8.7) -> 38.548983 | N13: =K13/F13 -> 0.076227348 | P13: =(sum(I8:I13)/sum(G8:G13)) -> 38.941707
A14: 40451 | B14: Barboursville | C14: West Virginia | D14: Sheetz | E14: 2.949 | F14: 3310 | G14: 7.153 | H14: 21.09 | I14: =if(G14>0,F14-F13," ") -> 275 | J14: =if(G14>0,I14/G13," ") -> 39.274493 | K14: =if(H14>0,K13+H14," ") -> 252.44 | L14: =G14+L13 -> 94.584 | M14: =F14/(L14-8.7) -> 38.540357 | N14: =K14/F14 -> 0.076265861 | P14: =(sum(I9:I14)/sum(G9:G14)) -> 38.327042
A15: 40452 | B15: Hillsville | C15: Virginia | D15: Liberty | E15: 2.729 | F15: =F14+197 -> 3507 | G15: 4.118 | H15: 11.24 | I15: =if(G15>0,F15-F14," ") -> 197 | J15: =if(G15>0,I15/G14," ") -> 27.540892 | K15: =if(H15>0,K14+H15," ") -> 263.68 | L15: =G15+L14 -> 98.702 | M15: =F15/(L15-8.7) -> 38.965801 | N15: =K15/F15 -> 0.075186769 | P15: =(sum(I10:I15)/sum(G10:G15)) -> 39.611964
A16: 40453 | B16: Waynesboro | C16: Virginia | D16: Sunoco | E16: 2.899 | F16: =F15+170 -> 3677 | G16: 5.688 | H16: 16.49 | I16: =if(G16>0,F16-F15," ") -> 170 | J16: =if(G16>0,I16/G15," ") -> 41.282176 | K16: =if(H16>0,K15+H16," ") -> 280.17 | L16: =G16+L15 -> 104.39 | M16: =F16/(L16-8.7) -> 38.426168 | N16: =K16/F16 -> 0.076195268 | P16: =(sum(I11:I16)/sum(G11:G16)) -> 37.64032
A17: 40458 | B17: Gettysburg | C17: Pennsylvania | D17: Sheetz | E17: 3.099 | F17: 4046 | G17: 6.845 | H17: 21.21 | I17: =if(G17>0,F17-F16," ") -> 369 | J17: =if(G17>0,I17/G16," ") -> 64.873418 | K17: =if(H17>0,K16+H17," ") -> 301.38 | L17: =G17+L16 -> 111.235 | M17: =F17/(L17-8.7) -> 39.459697 | N17: =K17/F17 -> 0.074488384 | P17: =(sum(I12:I17)/sum(G12:G17)) -> 41.596606
A18: 40458 | B18: Danbury | C18: Connecticut | D18: Mobil | E18: 3.159 | F18: 4349 | G18: 8.07 | H18: 25.49 | I18: =if(G18>0,F18-F17," ") -> 303 | J18: =if(G18>0,I18/G18," ") -> 37.546468 | K18: =if(H18>0,K17+H18," ") -> 326.87 | L18: =G18+L17 -> 119.305 | M18: =F18/(L18-8.7) -> 39.320103 | N18: =K18/F18 -> 0.075159807 | P18: =(sum(I13:I18)/sum(G13:G18)) -> 41.285112
A19: 40460 | B19: Charlton | C19: Massachusetts | D19: Gulf | E19: 3.049 | F19: 4684 | G19: 8.499 | H19: 25.91 | I19: =if(G19>0,F19-F18," ") -> 335 | J19: =if(G19>0,I19/G19," ") -> 39.416402 | K19: =if(H19>0,K18+H19," ") -> 352.78 | L19: =G19+L18 -> 127.804 | M19: =F19/(L19-8.7) -> 39.326975 | N19: =K19/F19 -> 0.075315969 | P19: =(sum(I14:I19)/sum(G14:G19)) -> 40.844128
A20: 40461 | B20: Austinburg | C20: Ohio | D20: Sunoco | E20: 3.079 | F20: 4982 | G20: 7.293 | H20: 22.46 | I20: =if(G20>0,F20-F19," ") -> 298 | J20: =if(G20>0,I20/G20," ") -> 40.8611 | K20: =if(H20>0,K19+H20," ") -> 375.24 | L20: =G20+L19 -> 135.097 | M20: =F20/(L20-8.7) -> 39.415492 | N20: =K20/F20 -> 0.075319149 | P20: =(sum(I15:I20)/sum(G15:G20)) -> 41.270703
A21: 40461 | B21: Warren | C21: Ohio | D21: Flying J | E21: 3.079 | F21: 5217 | G21: 5.762 | H21: 17.74 | I21: =if(G21>0,F21-F20," ") -> 235 | J21: =if(G21>0,I21/G21," ") -> 40.78445 | K21: =if(H21>0,K20+H21," ") -> 392.98 | L21: =G21+L20 -> 140.859 | M21: =F21/(L21-8.7) -> 39.475178 | N21: =K21/F21 -> 0.075326816 | P21: =(sum(I16:I21)/sum(G16:G21)) -> 40.562659
A22: 40462 | B22: Dayton | C22: Ohio | D22: Marathon | E22: 2.899 | F22: 5465 | G22: 7.069 | H22: 20.42 | I22: =if(G22>0,F22-F21," ") -> 248 | J22: =if(G22>0,I22/G22," ") -> 35.082756 | K22: =if(H22>0,K21+H22," ") -> 413.4 | L22: =G22+L21 -> 147.928 | M22: =F22/(L22-8.7) -> 39.252162 | N22: =K22/F22 -> 0.075645014 | P22: =(sum(I17:I22)/sum(G17:G22)) -> 41.067573
A23: 40462 | B23: Altamont | C23: Illinois | D23: Marathon | E23: 3.129 | F23: 5730 | G23: 6.047 | H23: 18.92 | I23: =if(G23>0,F23-F22," ") -> 265 | J23: =if(G23>0,I23/G23," ") -> 43.823383 | K23: =if(H23>0,K22+H23," ") -> 432.32 | L23: =G23+L22 -> 153.975 | M23: =F23/(L23-8.7) -> 39.442437 | N23: =K23/F23 -> 0.075448517 | P23: =(sum(I18:I23)/sum(G18:G23)) -> 39.401029
A24: 40487 | B24: Effingham | C24: Illinois | D24: Mobil | E24: 3.139 | F24: 5957 | G24: 6.48 | H24: 20.37 | I24: =if(G24>0,F24-F23," ") -> 227 | J24: =if(G24>0,I24/G24," ") -> 35.030864 | K24: =if(H24>0,K23+H24," ") -> 452.69 | L24: =G24+L23 -> 160.455 | M24: =F24/(L24-8.7) -> 39.254061 | N24: =K24/F24 -> 0.075992949 | P24: =(sum(I19:I24)/sum(G19:G24)) -> 39.076549
A25: 40488 | B25: Springfield | C25: Ohio | D25: Shell | E25: 3.259 | F25: 6230 | G25: 7.275 | H25: 23.71 | I25: =if(G25>0,F25-F24," ") -> 273 | J25: =if(G25>0,I25/G25," ") -> 37.525773 | K25: =if(H25>0,K24+H25," ") -> 476.4 | L25: =G25+L24 -> 167.73 | M25: =F25/(L25-8.7) -> 39.174998 | N25: =K25/F25 -> 0.0764687 | P25: =(sum(I20:I25)/sum(G20:G25)) -> 38.721635
A26: 40489 | B26: Waynesboro | C26: Pennsylvania | D26: Sheetz | E26: 3.199 | F26: =int((39.17*6.123)+6230) -> 6469 | G26: 6.123 | H26: 19.59 | I26: =if(G26>0,F26-F25," ") -> 239 | J26: =if(G26>0,I26/G26," ") -> 39.033154 | K26: =if(H26>0,K25+H26," ") -> 495.99 | L26: =G26+L25 -> 173.853 | M26: =F26/(L26-8.7) -> 39.16974 | N26: =K26/F26 -> 0.076671819 | P26: =(sum(I21:I26)/sum(G21:G26)) -> 38.368253
A27: 40490 | B27: Middleton | C27: Pennsylvania | D27: Sunoco | E27: 3.159 | F27: 6748 | G27: 6.255 | H27: 19.76 | I27: =if(G27>0,F27-F26," ") -> 279 | J27: =if(G27>0,I27/G27," ") -> 44.604317 | K27: =if(H27>0,K26+H27," ") -> 515.75 | L27: =G27+L26 -> 180.108 | M27: =F27/(L27-8.7) -> 39.368057 | N27: =K27/F27 -> 0.076430053 | P27: =(sum(I22:I27)/sum(G22:G27)) -> 39.007363
A28: 40491 | B28: Newburg | C28: Pennsylvania | D28: Sunoco | E28: 3.149 | F28: 6991 | G28: 5.985 | H28: 18.85 | I28: =if(G28>0,F28-F27," ") -> 243 | J28: =if(G28>0,I28/G28," ") -> 40.601504 | K28: =if(H28>0,K27+H28," ") -> 534.6 | L28: =G28+L27 -> 186.093 | M28: =F28/(L28-8.7) -> 39.409672 | N28: =K28/F28 -> 0.076469747 | P28: =(sum(I23:I28)/sum(G23:G28)) -> 39.984279
A29: 40492 | B29: Pittsburgh | C29: Pennsylvania | D29: Sunoco | E29: 3.109 | F29: 7271 | G29: 7.989 | H29: 24.84 | I29: =if(G29>0,F29-F28," ") -> 280 | J29: =if(G29>0,I29/G29," ") -> 35.048191 | K29: =if(H29>0,K28+H29," ") -> 559.44 | L29: =G29+L28 -> 194.082 | M29: =F29/(L29-8.7) -> 39.221715 | N29: =K29/F29 -> 0.076941274 | P29: =(sum(I24:I29)/sum(G24:G29)) -> 38.422221
A30: 40496 | B30: Summerville | C30: West Virginia | D30: Sunoco | E30: 3.139 | F30: 7531 | G30: 6.94 | H30: 21.78 | I30: =if(G30>0,F30-F29," ") -> 260 | J30: =if(G30>0,I30/G30," ") -> 37.463977 | K30: =if(H30>0,K29+H30," ") -> 581.22 | L30: =G30+L29 -> 201.022 | M30: =F30/(L30-8.7) -> 39.158287 | N30: =K30/F30 -> 0.077177002 | P30: =(sum(I25:I30)/sum(G25:G30)) -> 38.80001
A31: 40497 | B31: Bessemer | C31: North Carolina | D31: Exxon | E31: 3.119 | F31: 7802 | G31: 6.581 | H31: 20.53 | I31: =if(G31>0,F31-F30," ") -> 271 | J31: =if(G31>0,I31/G31," ") -> 41.179152 | K31: =if(H31>0,K30+H31," ") -> 601.75 | L31: =G31+L30 -> 207.603 | M31: =F31/(L31-8.7) -> 39.22515 | N31: =K31/F31 -> 0.07712766 | P31: =(sum(I26:I31)/sum(G26:G31)) -> 39.425175
A32: 40498 | B32: Villa Rica | C32: Georgia | D32: Shell | E32: 3.099 | F32: 8068 | G32: 6.482 | H32: 20.09 | I32: =if(F32>0,F32-F31," ") -> 266 | J32: =if(G32>0,I32/G32," ") -> 41.036717 | K32: =if(H32>0,K31+H32," ") -> 621.84 | L32: =G32+L31 -> 214.085 | M32: =F32/(L32-8.7) -> 39.282323 | N32: =K32/F32 -> 0.077074864 | P32: =(sum(I27:I32)/sum(G27:G32)) -> 39.744482
A33: 40498 | B33: Tupelo | C33: Mississippi | D33: Love | E33: 2.899 | F33: 8317 | G33: 6.997 | H33: 20.28 | I33: =if(F33>0,F33-F32," ") -> 249 | J33: =if(G33>0,I33/G33," ") -> 35.58668 | K33: =if(H33>0,K32+H33," ") -> 642.12 | L33: =G33+L32 -> 221.082 | M33: =F33/(L33-8.7) -> 39.160569 | N33: =K33/F33 -> 0.077205723 | P33: =(sum(I28:I33)/sum(G28:G33)) -> 38.292576
A34: 40499 | B34: Bryant | C34: Arkansas | D34: Superstop | E34: 2.929 | F34: 8574 | G34: 6.564 | H34: 19.22 | I34: =if(F34>0,F34-F33," ") -> 257 | J34: =if(G34>0,I34/G34," ") -> 39.152956 | K34: =if(H34>0,K33+H34," ") -> 661.34 | L34: =G34+L33 -> 227.646 | M34: =F34/(L34-8.7) -> 39.160341 | N34: =K34/F34 -> 0.077133193 | P34: =(sum(I29:I34)/sum(G29:G34)) -> 38.095926
A35: 40499 | B35: Mt Pleasant | C35: Texas | D35: Exxon | E35: 3.099 | F35: 8756 | G35: 5.54 | H35: 17.17 | I35: =if(F35>0,F35-F34," ") -> 182 | J35: =if(G35>0,I35/G35," ") -> 32.851986 | K35: =if(H35>0,K34+H35," ") -> 678.51 | L35: =G35+L34 -> 233.186 | M35: =F35/(L35-8.7) -> 39.00466 | N35: =K35/F35 -> 0.077490863 | P35: =(sum(I30:I35)/sum(G30:G35)) -> 37.975655
A36: 40503 | B36: Weatherford | C36: Texas | D36: Mobil | E36: 3.199 | F36: 9005 | G36: 6.232 | H36: 19.94 | I36: =if(F36>0,F36-F35," ") -> 249 | J36: =if(G36>0,I36/G36," ") -> 39.955071 | K36: =if(H36>0,K35+H36," ") -> 698.45 | L36: =G36+L35 -> 239.418 | M36: =F36/(L36-8.7) -> 39.030331 | N36: =K36/F36 -> 0.077562465 | P36: =(sum(I31:I36)/sum(G31:G36)) -> 38.389416
A37: 40503 | B37: Big Springs | C37: Texas | D37: Shell | E37: 3.099 | F37: 9230 | G37: 6.795 | H37: 21.06 | I37: =if(F37>0,F37-F36," ") -> 225 | J37: =if(G37>0,I37/G37," ") -> 33.112583 | K37: =if(H37>0,K36+H37," ") -> 719.51 | L37: =G37+L36 -> 246.213 | M37: =F37/(L37-8.7) -> 38.861031 | N37: =K37/F37 -> 0.077953413 | P37: =(sum(I32:I37)/sum(G32:G37)) -> 36.985237
A38: 40503 | B38: Carlsbad | C38: New Mexico | D38: Shell | E38: 2.899 | F38: 9430 | G38: 5.849 | H38: 16.96 | I38: =if(F38>0,F38-F37," ") -> 200 | J38: =if(G38>0,I38/G38," ") -> 34.193879 | K38: =if(H38>0,K37+H38," ") -> 736.47 | L38: =G38+L37 -> 252.062 | M38: =F38/(L38-8.7) -> 38.74886 | N38: =K38/F38 -> 0.078098621 | P38: =(sum(I33:I38)/sum(G33:G38)) -> 35.863812
A39: 40504 | B39: Ruidosa | C39: New Mexico | D39: Circle K | E39: 3.029 | F39: 9633 | G39: 5.666 | H39: 17.16 | I39: =if(F39>0,F39-F38," ") -> 203 | J39: =if(G39>0,I39/G39," ") -> 35.827744 | K39: =if(H39>0,K38+H39," ") -> 753.63 | L39: =G39+L38 -> 257.728 | M39: =F39/(L39-8.7) -> 38.682397 | N39: =K39/F39 -> 0.078234195 | P39: =(sum(I34:I39)/sum(G34:G39)) -> 35.91115
A40: 40505 | B40: Willcox | C40: Arizona | D40: Shell | E40: 3.089 | F40: 9944 | G40: 7.185 | H40: 22.19 | I40: =if(F40>0,F40-F39," ") -> 311 | J40: =if(G40>0,I40/G40," ") -> 43.284621 | K40: =if(H40>0,K39+H40," ") -> 775.82 | L40: =G40+L39 -> 264.913 | M40: =F40/(L40-8.7) -> 38.811458 | N40: =K40/F40 -> 0.078018906 | P40: =(sum(I35:I40)/sum(G35:G40)) -> 36.761746
...

Sheet Locations
A1: Date | B1: City | C1: State | E1: =concatenate(A1,", ",B1,", ",C1) -> Date, City, State
A2: 40382 | B2: San Diego | C2: California | E2: =concatenate(TEXT(A2,"M/d/yyyy"),", ",B2,", ",C2) -> 7/23/2010, San Diego, California
A3: 40385 | B3: San Marcos | C3: California | E3: =concatenate(TEXT(A3,"M/d/yyyy"),", ",B3,", ",C3) -> 7/26/2010, San Marcos, California
A4: 40440 | B4: Campo | C4: California | E4: =concatenate(TEXT(A4,"M/d/yyyy"),", ",B4,", ",C4) -> 9/19/2010, Campo, California
A5: 40440 | B5: Eloy | C5: Arizona | E5: =concatenate(TEXT(A5,"M/d/yyyy"),", ",B5,", ",C5) -> 9/19/2010, Eloy, Arizona
A6: 40441 | B6: Deming | C6: Arizona | E6: =concatenate(TEXT(A6,"M/d/yyyy"),", ",B6,", ",C6) -> 9/20/2010, Deming, Arizona
A7: 40441 | B7: Pecos | C7: Texas | E7: =concatenate(TEXT(A7,"M/d/yyyy"),", ",B7,", ",C7) -> 9/20/2010, Pecos, Texas
A8: 40442 | B8: Abilene | C8: Texas | E8: =concatenate(TEXT(A8,"M/d/yyyy"),", ",B8,", ",C8) -> 9/21/2010, Abilene, Texas
A9: 40444 | B9: Flower Mound | C9: Texas | E9: =concatenate(TEXT(A9,"M/d/yyyy"),", ",B9,", ",C9) -> 9/23/2010, Flower Mound, Texas
A10: 40445 | B10: Blackwell | C10: Oklahoma | E10: =concatenate(TEXT(A10,"M/d/yyyy"),", ",B10,", ",C10) -> 9/24/2010, Blackwell, Oklahoma
A11: 40445 | B11: Matfield Green | C11: Kansas | E11: =concatenate(TEXT(A11,"M/d/yyyy"),", ",B11,", ",C11) -> 9/24/2010, Matfield Green, Kansas
A12: 40450 | B12: St. Louis | C12: Missouri | E12: =concatenate(TEXT(A12,"M/d/yyyy"),", ",B12,", ",C12) -> 9/29/2010, St. Louis, Missouri
A13: 40451 | B13: Dale | C13: Indiana | E13: =concatenate(TEXT(A13,"M/d/yyyy"),", ",B13,", ",C13) -> 9/30/2010, Dale, Indiana
... A116: 41060 | B116: Champaign | C116: Illinois | E116: =concatenate(TEXT(A116,"M/d/yyyy"),", ",B116,", ",C116) -> 5/31/2012, Champaign, Illinois
A117: 5/31/0202 | B117: Richmond | C117: Ohio | E117: =concatenate(TEXT(A117,"M/d/yyyy"),", ",B117,", ",C117) -> 5/31/0202, Richmond, Ohio
A118: 41061 | B118: Morgantown | C118: West Virginia | E118: =concatenate(TEXT(A118,"M/d/yyyy"),", ",B118,", ",C118) -> 6/1/2012, Morgantown, West Virginia
A119: 41068 | B119: Morgantown | C119: West Virginia | E119: =concatenate(TEXT(A119,"M/d/yyyy"),", ",B119,", ",C119) -> 6/8/2012, Morgantown, West Virginia
A120: 41069 | B120: Clyde | C120: Ohio | E120: =concatenate(TEXT(A120,"M/d/yyyy"),", ",B120,", ",C120) -> 6/9/2012, Clyde, Ohio
A121: 41069 | B121: Jackson | C121: Michigan | E121: =concatenate(TEXT(A121,"M/d/yyyy"),", ",B121,", ",C121) -> 6/9/2012, Jackson, Michigan
A122: 41071 | B122: Madison | C122: Wisconsin | E122: =concatenate(TEXT(A122,"M/d/yyyy"),", ",B122,", ",C122) -> 6/11/2012, Madison, Wisconsin
A123: 41071 | B123: Hudson | C123: Wisconsin | E123: =concatenate(TEXT(A123,"M/d/yyyy"),", ",B123,", ",C123) -> 6/11/2012, Hudson, Wisconsin
A124: 41072 | B124: Rothsay | C124: Minnesota | E124: =concatenate(TEXT(A124,"M/d/yyyy"),", ",B124,", ",C124) -> 6/12/2012, Rothsay, Minnesota
A125: 41072 | B125: Bismarck | C125: North Dakota | E125: =concatenate(TEXT(A125,"M/d/yyyy"),", ",B125,", ",C125) -> 6/12/2012, Bismarck, North Dakota
A126: 41073 | B126: Beach | C126: North Dakota | E126: =concatenate(TEXT(A126,"M/d/yyyy"),", ",B126,", ",C126) -> 6/13/2012, Beach, North Dakota
A127: 41074 | B127: Billings | C127: Montana | E127: =concatenate(TEXT(A127,"M/d/yyyy"),", ",B127,", ",C127) -> 6/14/2012, Billings, Montana
A128: 41074 | B128: Livingston | C128: Montana | E128: =concatenate(TEXT(A128,"M/d/yyyy"),", ",B128,", ",C128) -> 6/14/2012, Livingston, Montana
A129: 41075 | B129: Pocatello | C129: Idaho | E129: =concatenate(TEXT(A129,"M/d/yyyy"),", ",B129,", ",C129) -> 6/15/2012, Pocatello, Idaho
... A213: 41802 | B213: Landcaster | C213: California | E213: =concatenate(TEXT(A213,"M/d/yyyy"),", ",B213,", ",C213) -> 6/12/2014, Landcaster, California

Sheet Trip Log
A1: Date | B1: Strt Time | C1: Temp | D1: ODO | E1: City | F1: End Time | G1: Temp | H1: ODO | I1: CIty | J1: Note
A2: 40605 | G2: 83 | H2: 11552 | I2: Lake San Marcos | J2: End of desert trip
A3: 40669 | B3: 0.23472222 | C3: 57 | D3: 11660 | E3: Lake San Marcos | I3: Livermore | J3: Start NoCal trip
A4: 40670 | B4: 0.32986111 | C4: 55 | D4: 12147 | E4: Livermore | I4: Trinidad
A5: 5/8/0201 | B5: 0.31944444 | C5: 47 | D5: 12508 | E5: Trinidad | I5: Trinidad
A6: 40672 | B6: 0.33611111 | C6: 46 | D6: 12610 | E6: Trinidad | I6: Healdsburg
A7: 40673 | B7: 0.43055556 | C7: 76 | D7: 12850 | E7: Healdsburg | I7: San Luis Obispo
A8: 40674 | B8: 0.35138889 | C8: 54 | D8: 13154 | E8: San Luis Obispo | F8: 0.725 | G8: 64 | H8: 13461 | I8: Lake San Marcos | J8: End of NoCal trip

Sheet Canada2014
A1: Date | B1: City | C1: Province | D1: Brand | E1: CN$/liter | F1: ODO | G1: Liters | H1: $CN | J1: US$/liter | K1: US$/gallon | L1: gallons | M1: Cost (USD)
A2: 41783 | B2: Timber River | C2: New Brunswick | D2: Petro-Canada | E2: 1.446 | F2: 45576 | G2: 24.194 | H2: 34.98 | J2: =E2*$F$24 -> 1.33032 | K2: =J2/$F$25 -> 5.03581 | L2: =G2*$F$25 -> 6.3913774 | M2: =H2*$F$24 -> 32.1816
A3: 41784 | B3: Belle Cote | C3: Nova Scotia | D3: Caper Gas | E3: 1.495 | F3: 45859 | G3: 25.157 | H3: 37.61 | J3: =E3*$F$24 -> 1.3754 | K3: =J3/$F$25 -> 5.2064564 | L3: =G3*$F$25 -> 6.645775 | M3: =H3*$F$24 -> 34.6012
A4: 41784 | B4: Sydney Mines | C4: Nova Scotia | D4: Petro-Canada | E4: 1.496 | F4: 46034 | G4: 15.42 | H4: 23.07 | J4: =E4*$F$24 -> 1.37632 | K4: =J4/$F$25 -> 5.209939 | L4: =G4*$F$25 -> 4.0735322 | M4: =H4*$F$24 -> 21.2244
A5: 41785 | B5: Corner Brook | C5: Newfoundland | D5: Esso | E5: 1.472 | F5: 46174 | G5: 13.416 | H5: 19.75 | J5: =E5*$F$24 -> 1.35424 | K5: =J5/$F$25 -> 5.1263571 | L5: =G5*$F$25 -> 3.5441316 | M5: =H5*$F$24 -> 18.17
A6: 41787 | B6: Woody Point | C6: Newfoundland | D6: Western Petroleum | E6: 1.412 | F6: 46421 | G6: 14.161 | H6: 20 | I6: partial | J6: =E6*$F$24 -> 1.29904 | K6: =J6/$F$25 -> 4.9174023 | L6: =G6*$F$25 -> 3.7409397 | M6: =H6*$F$24 -> 18.4
A7: 41787 | B7: Port Aux Basques | C7: Newfoundland | D7: Irving | E7: 1.48 | F7: 46617 | G7: 26.952 | H7: 39.89 | J7: =E7*$F$24 -> 1.3616 | K7: =J7/$F$25 -> 5.1542177 | L7: =G7*$F$25 -> 7.1199637 | M7: =H7*$F$24 -> 36.6988
A8: 41788 | B8: Aulac | C8: New Brunswick | D8: Irving | E8: 1.432 | F8: 46881 | G8: 22.162 | H8: 31.74 | J8: =E8*$F$24 -> 1.31744 | K8: =J8/$F$25 -> 4.9870539 | L8: =G8*$F$25 -> 5.8545799 | M8: =H8*$F$24 -> 29.2008
A9: 41788 | B9: Beardsley | C9: New Brunswick | D9: Irving | E9: 1.453 | F9: 47075 | G9: 23.67 | H9: 34.4 | J9: =E9*$F$24 -> 1.33676 | K9: =J9/$F$25 -> 5.0601881 | L9: =G9*$F$25 -> 6.2529512 | M9: =H9*$F$24 -> 31.648
A10: 41789 | B10: St. Jean-Pont Joli | C10: Quebec | D10: Petro-Canada | E10: 1.529 | F10: 47306 | G10: 19.36 | H10: 29.6 | J10: =E10*$F$24 -> 1.40668 | K10: =J10/$F$25 -> 5.3248641 | L10: =G10*$F$25 -> 5.1143699 | M10: =H10*$F$24 -> 27.232
A11: 41791 | B11: Saint Lazare | C11: Quebec | D11: Esso | E11: 1.549 | F11: 47553 | G11: 25.454 | H11: 39.43 | J11: =E11*$F$24 -> 1.42508 | K11: =J11/$F$25 -> 5.3945157 | L11: =G11*$F$25 -> 6.7242341 | M11: =H11*$F$24 -> 36.2756
A12: 41791 | B12: North Bay | C12: Ontario | D12: Shell | E12: 1.489 | F12: 47855 | G12: 26.52 | H12: 39.49 | J12: =E12*$F$24 -> 1.36988 | K12: =J12/$F$25 -> 5.1855609 | L12: =G12*$F$25 -> 7.0058414 | M12: =H12*$F$24 -> 36.3308
A13: 41792 | B13: Sault St. Marie | C13: Ontario | D13: Husky | E13: 1.559 | F13: 48114 | G13: 22.534 | H13: 35.13 | J13: =E13*$F$24 -> 1.43428 | K13: =J13/$F$25 -> 5.4293415 | L13: =G13*$F$25 -> 5.9528518 | M13: =H13*$F$24 -> 32.3196
A14: 41793 | B14: Wawa | C14: Ontario | D14: Petro-Canada | E14: 1.629 | F14: 48266 | G14: 13.286 | H14: 21.64 | J14: =E14*$F$24 -> 1.49868 | K14: =J14/$F$25 -> 5.6731221 | L14: =G14*$F$25 -> 3.5097892 | M14: =H14*$F$24 -> 19.9088
A15: 41793 | B15: Shuniah | C15: Ontario | D15: Flying J | E15: 1.549 | F15: 48526 | G15: 22.813 | H15: 35.34 | J15: =E15*$F$24 -> 1.42508 | K15: =J15/$F$25 -> 5.3945157 | L15: =G15*$F$25 -> 6.0265558 | M15: =H15*$F$24 -> 32.5128
A16: 41794 | B16: Dryden | C16: Ontario | D16: Petro-Canada | E16: 1.529 | F16: 48778 | G16: 24.24 | H16: 37.06 | J16: =E16*$F$24 -> 1.40668 | K16: =J16/$F$25 -> 5.3248641 | L16: =G16*$F$25 -> 6.4035293 | M16: =H16*$F$24 -> 34.0952
A17: 41795 | B17: Brandon | C17: Manitoba | D17: Shell | E17: 1.469 | F17: 49122 | G17: 26.727 | H17: 39.26 | J17: =E17*$F$24 -> 1.35148 | K17: =J17/$F$25 -> 5.1159093 | L17: =G17*$F$25 -> 7.060525 | M17: =H17*$F$24 -> 36.1192
A18: 41796 | B18: Regina | C18: Saskatchwan | D18: Shell | E18: 1.489 | F18: 49344 | G18: 22.092 | H18: 32.89 | J18: =E18*$F$24 -> 1.36988 | K18: =J18/$F$25 -> 5.1855609 | L18: =G18*$F$25 -> 5.8360878 | M18: =H18*$F$24 -> 30.2588
... A20: 41797 | B20: Blairmore | C20: Alberta | D20: Shell | E20: 1.449 | F20: 49822 | G20: 22.78 | H20: 33 | J20: =E20*$F$24 -> 1.33308 | K20: =J20/$F$25 -> 5.0462577 | L20: =G20*$F$25 -> 6.0178382 | M20: =H20*$F$24 -> 30.36
E24: US/Canada rate | F24: 0.92
E25: liters to gallons | F25: 0.264172
